Workbook

Sheet 東方Wiki
A1: from | B1: http://thwiki.info/?%BD%D0%B1%E9%A5%EA%A5%B9%A5%C8 | AH1: from
A2: 番号 | B2: 1~5 | C2: 6 | D2: 7 | E2: 8 | F2: 7.5 | G2: 9 | H2: 9.5 | I2: 9.5 | J2: 10 | K2: 10.5 | L2: 11 | M2: 12 | N2: 12.3 | O2: 12.5 | P2: 12.8 | Q2: 13 | R2: 13.5 | S2: 14 | T2: 14.3 | U2: 14.5 | V2: 15 | W2: 16 | X2: 15.5 | Y2: 16.5 | Z2: 17 | AA2: 18 | AB2: 17.5 | AC2: 18.5
A3: 年 | B3: 2000 | C3: 2002 | D3: 2003 | E3: 2004 | F3: 2004 | G3: 2005 | H3: 2005 | I3: 2005 | J3: 2007 | K3: 2008 | L3: 2008 | M3: 2009 | N3: 2009 | O3: 2010 | P3: 2010 | Q3: 2011 | R3: 2013 | S3: 2013 | T3: 2014 | U3: 2015 | V3: 2015 | W3: 2017 | X3: 2017 | Y3: 2018 | Z3: 2019 | AA3: 2021 | AB3: 2021 | AC3: 2022 | AH3: 年
A4: 人気投票 | C4: 1 | D4: 2 | E4: 3 | G4: 4 | K4: 5 | M4: 6 | AH4: 人気投票
B5: 旧作-西方 | C5: 紅魔郷 | D5: 妖々夢 | E5: 永夜抄 | F5: 萃夢想 | G5: 花映塚 | H5: 文 (書籍) | I5: 文(STG) | J5: 風神録 | K5: 緋想天 | L5: 地霊殿 | M5: 星蓮船 | N5: 非想天則 | O5: DS | P5: 妖精大戦争 | Q5: 神霊廟 | R5: 心綺楼 | S5: 輝針城 | T5: 天邪鬼 | U5: 深秘録 | V5: 紺珠伝 | W5: 天空璋 | X5: 憑依華 | Y5: 秘封ナイトメアダイアリー | Z5: 鬼形獣 | AA5: 虹龍洞 | AB5: 剛欲異聞 | AC5: バレットフィリア達の闇市場 | AG5: 備考
A6: 博麗 霊夢 | B6: 1 | C6: 自機 | D6: 自機 | E6: 自機 4中ボス 4ボス | F6: 自機 | G6: 自機 | H6: ○ | I6: ※2 | J6: 自機 | K6: 自機 | L6: 自機 | M6: 自機 | N6: 自機 | O6: Ex | P6: B-1ED | Q6: 自機 | R6: 自機 | S6: 自機 | T6: 8日目 | U6: 自機 | V6: 自機 | W6: 自機 | X6: 自機 | AG6: ※旧作 全部- 秋霜玉Exボス ※2おまけtxtのみ | AH6: 博麗 霊夢
A7: 霧雨 魔理沙 | B7: 1 | C7: 自機 | D7: 自機 | E7: 自機 4中ボス 4ボス | F7: 自機 | G7: 自機 | H7: ○ | I7: ※2 | J7: 自機 | K7: 自機 | L7: 自機 | M7: 自機 | N7: 自機 | O7: Ex | P7: Exボス | Q7: 自機 | R7: 自機 | S7: 自機 | T7: 7日目 | U7: 自機 | V7: 自機 | W7: 自機 | X7: 自機 | AG7: ※旧作 封魔録から- 秋霜玉Exボス Win版東方STGアイコン ※2おまけtxtのみ | AH7: 霧雨 魔理沙
A8: ルーミア | C8: 1中ボス 1ボス | H8: ○ | I8: Lv1 | R8: ※ | AG8: ※背景に登場（夢殿大祀廟） | AH8: ルーミア
A9: 大妖精 | C9: 2中ボス | P9: 1中ボス 2中ボス EX中ボス | AH9: 大妖精
A10: チルノ | C10: 2ボス | D10: 1中ボス | G10: 自機 | H10: ○ | I10: Lv2 | N10: 自機 | P10: 自機 | R10: ※ | S10: 1中ボス | T10: 1日目 | W10: 自機 | AG10: ※背景に登場（夢殿大祀廟・妖怪狸の森） | AH10: チルノ
A11: 紅 美鈴 | C11: 3中ボス 3ボス | F11: 自機※ | H11: ○ | I11: Lv5 | N11: 自機 | AG11: ※ストーリーなし | AH11: 紅 美鈴
A12: 小悪魔 | C12: 4中ボス | AH12: 小悪魔
A13: パチュリー・ノーレッジ | C13: 4ボス Ex中ボス | D13: 幻符ED | E13: 紅魔組ED | F13: 自機 | G13: 咲夜ED | H13: ○ | I13: Lv5 | K13: 自機 | L13: 支援-魔理沙 | N13: 自機 | R13: ※ | AG13: ※背景に登場（博麗神社） | AH13: パチュリー・ノーレッジ
A14: 十六夜 咲夜 | C14: 5中ボス 5ボス 6中ボス | D14: 自機 | E14: 自機 | F14: 自機 | G14: 自機 | H14: ○ | I14: Lv7 | K14: 自機 | N14: 自機 | R14: ※ | S14: 自機 | T14: 7日目 | AG14: ※背景に登場（博麗神社） | AH14: 十六夜 咲夜
A15: レミリア・スカーレット | C15: 6ボス | D15: 霊符ED 咲夜ED | E15: 自機 | F15: 自機 | G15: 咲夜ED | H15: ○ | I15: Lv7 | J15: 霊夢B ED※ | K15: 自機 | N15: 自機 | R15: ※2 | T15: 最終日 | AG15: ※霊夢の想像、台詞なし ※2背景に登場（博麗神社） | AH15: レミリア・スカーレット
A16: フランドール・スカーレット | C16: Exボス | H16: ○ | I16: Ex | AH16: フランドール・スカーレット
A17: レティ・ホワイトロック | D17: 1ボス | H17: ○ | I17: Lv2 | R17: ※ | AG17: ※背景に登場（夢殿大祀廟） | AH17: レティ・ホワイトロック
A18: 橙 | D18: 2中ボス 2ボス Ex中ボス | E18: 結界組ED | F18: ※ | H18: ○ | I18: Lv6 | K18: ※※ | N18: ※※ | R18: ※2 | AG18: ※八雲藍＋の弾 ※※紫の弾 ※2背景に登場（博麗神社） | AH18: 橙
A19: アリス・マーガトロイド | B19: 1 | D19: 3中ボス 3ボス | E19: 自機 | F19: 自機 | H19: ○ | I19: Lv3 | K19: 自機 | L19: 支援-魔理沙 | N19: 自機 | R19: ※2 | AG19: ※怪綺談3- EXボス ※2背景に登場（人間の里） | AH19: アリス・マーガトロイド
A20: リリーホワイト | D20: 4中ボス | G20: 敵 | P20: 1中ボス 2中ボス EX中ボス | R20: ※ | W20: 1 | AG20: ※背景に登場（雲上の宝船・夢殿大祀廟・妖怪狸の森） | AH20: リリーホワイト
A21: ルナサ・プリズムリバー | D21: 4ボス | G21: 自機※ | H21: ○ | R21: ※2 | AG21: ※ストーリーなし ※2背景に登場（雲上の宝船・神霊廟） | AH21: ルナサ・プリズムリバー
A22: メルラン・プリズムリバー | D22: 4ボス | G22: 自機※ | H22: ○ | R22: ※2 | AG22: ※ストーリーなし ※2背景に登場（雲上の宝船・神霊廟） | AH22: メルラン・プリズムリバー
A23: リリカ・プリズムリバー | D23: 4ボス | G23: 自機 | H23: ○ | R23: ※ | AG23: ※背景に登場（雲上の宝船・神霊廟） | AH23: リリカ・プリズムリバー
A24: 魂魄 妖夢 | D24: 5中ボス 5ボス 6中ボス | E24: 自機 | F24: 自機 | G24: 自機 | H24: ○ | I24: Lv6 | K24: 自機 | N24: 自機 | Q24: 自機 | R24: ※ | T24: 7日目 | AG24: ※背景に登場（神霊廟） | AH24: 魂魄 妖夢
A25: 西行寺 幽々子 | D25: 6ボス | E25: 自機 | F25: 自機 | G25: 妖夢ED | H25: ○ | I25: Lv8 | K25: 自機 | N25: 自機 | Q25: 1ボス | R25: ※ | T25: 4日目 | AG25: ※背景に登場（神霊廟） | AH25: 西行寺 幽々子
A26: 八雲 藍 | D26: Exボス Ph中ボス | E26: ※ 結界組ED | F26: ※ | H26: ○ | I26: Lv8 | K26: ※ | N26: ※ | R26: ※2 | AG26: ※紫の弾 ※2背景に登場（博麗神社） | AH26: 八雲 藍
A27: 八雲 紫 | D27: Phボス | E27: 自機 | F27: 自機 | H27: ○ | I27: Ex | K27: 自機 | L27: 支援-霊夢 | N27: 自機 | R27: ※ | T27: 最終日 | V27: 魔理沙 完ED | AG27: ※背景に登場（博麗神社） | AH27: 八雲 紫
A28: リグル・ナイトバグ | E28: 1中ボス 1ボス | H28: ○ | I28: Lv1 | R28: ※ | AG28: ※背景に登場（夢殿大祀廟・妖怪狸の森） | AH28: リグル・ナイトバグ
A29: ミスティア・ローレライ | E29: 2中ボス 2ボス | G29: 自機 | H29: ○ | R29: ※ | AG29: ※背景に登場（夢殿大祀廟） | AH29: ミスティア・ローレライ
A30: 上白沢 慧音 | E30: 3中ボス 3ボス Ex中ボス※ | H30: ○ | I30: Lv3 | R30: ※2 | T30: 3日目 | AG30: ※Exにはハクタク状態で登場 ※2背景に登場（人間の里） | AH30: 上白沢 慧音
A31: 因幡 てゐ | E31: 5中ボス | G31: 自機 | H31: ○ | I31: Lv4 | R31: ※ | V31: 霊夢 完ED | AG31: ※背景に登場（人間の里） | AH31: 因幡 てゐ
A32: 鈴仙・優曇華院・イナバ | E32: 5ボス | G32: 自機 | H32: ○ | I32: Lv4 | K32: 自機 | N32: 自機 | R32: ※ | U32: 自機※2 | V32: 自機 | AG32: ※背景に登場（人間の里） ※2PS4版で追加 | AH32: 鈴仙・優曇華院・イナバ
A33: 八意 永琳 | E33: 6A中ボス 6Aボス 6B中ボス | G33: ED※ | H33: ○ | I33: Lv9 | K33: 鈴仙ED | R33: ※2 | V33: あらすじ ED※3 | AG33: ※鈴仙・てゐ・メディスン ※2背景に登場（人間の里） ※3霊夢 完・鈴仙 完 | AH33: 八意 永琳
A34: 蓬莱山 輝夜 | E34: 6Bボス | H34: ○ | I34: Lv9 | R34: ※ | V34: あらすじ 鈴仙 レED | AG34: ※背景に登場（人間の里） | AH34: 蓬莱山 輝夜
A35: 藤原 妹紅 | E35: Exボス | H35: ○ | I35: Ex | R35: ※ | T35: 3日目 | U35: 自機 | AG35: ※背景に登場（人間の里） | AH35: 藤原 妹紅
A36: 伊吹 萃香 | F36: 自機 | H36: ○ | I36: Ex | K36: 自機 | L36: 支援-霊夢 | N36: 自機 | O36: Lv6 | R36: ※ | T36: 9日目 | AG36: ※背景に登場（人間の里） | AH36: 伊吹 萃香
A37: 射命丸 文 | G37: 自機 | H37: ○ | I37: 自機 | J37: 4ボス | K37: 自機 | L37: 支援-霊夢 | N37: 自機 | O37: 自機 Sp | P37: C-1ED | R37: ※ | T37: 6日目 | W37: 自機 | AG37: ※背景に登場（命蓮寺・玄武の沢） | AH37: 射命丸 文
A38: メディスン・メランコリー | G38: 自機 | I38: Lv4 | R38: ※ | AG38: ※背景に登場（夢殿大祀廟） | AH38: メディスン・メランコリー
A39: 風見 幽香 | B39: 1 | G39: 自機 | R39: ※2 | AG39: ※幻想郷5-6ボス 怪奇談自機-稀翁玉自機 ※2背景に登場（夢殿大祀廟） | AH39: 風見 幽香
A40: 小野塚 小町 | G40: 自機 | I40: Lv10 | K40: 自機 | N40: 自機 | R40: ※ | AG40: ※背景に登場（神霊廟） | AH40: 小野塚 小町
...

Sheet キャラ初出
B1: 初出作品 | C1: 初出番号 | D1: 初出年 | E1: 投票初出回 | F1: CD(秘封) | G1: 書籍のみ | H1: 整数boss | I1: 整数自機 | J1: 非整数自機 | K1: 非整数boss | L1: 整数自機回数 | M1: 非整数自機回数 | N1: old_charid
A2: 博麗 霊夢 | B2: {=XLOOKUP(C2,'作品サブタイトル'!$A$2:$A$32,'作品サブタイトル'!$F$2:$F$32,0)} -> 靈異伝 | C2: 1 | D2: {=XLOOKUP(C2,'作品サブタイトル'!$A$2:$A$32,'作品サブタイトル'!$B$2:$B$32,0)} -> 1996 | E2: {=xlookup(C2,'作品サブタイトル'!A$2:A$32,'作品サブタイトル'!E$2:E$32)} -> 1 | F2: 0 | G2: 0 | H2: 0 | I2: 1 | J2: 1 | K2: 1 | L2: 30 | N2: 0
A3: 霧雨 魔理沙 | B3: {=XLOOKUP(C3,'作品サブタイトル'!$A$2:$A$32,'作品サブタイトル'!$F$2:$F$32,0)} -> 封魔録 | C3: 2 | D3: {=XLOOKUP(C3,'作品サブタイトル'!$A$2:$A$32,'作品サブタイトル'!$B$2:$B$32,0)} -> 1997 | E3: {=xlookup(C3,'作品サブタイトル'!A$2:A$32,'作品サブタイトル'!E$2:E$32)} -> 1 | F3: 0 | G3: 0 | H3: 0 | I3: 1 | J3: 1 | K3: 1 | L3: 30 | N3: 1
A4: ルーミア | B4: {=XLOOKUP(C4,'作品サブタイトル'!$A$2:$A$32,'作品サブタイトル'!$F$2:$F$32,0)} -> 紅魔郷 | C4: 6 | D4: {=XLOOKUP(C4,'作品サブタイトル'!$A$2:$A$32,'作品サブタイトル'!$B$2:$B$32,0)} -> 2002 | E4: {=xlookup(C4,'作品サブタイトル'!A$2:A$32,'作品サブタイトル'!E$2:E$32)} -> 1 | F4: 0 | G4: 0 | H4: 1 | N4: 2
A5: 大妖精 | B5: {=XLOOKUP(C5,'作品サブタイトル'!$A$2:$A$32,'作品サブタイトル'!$F$2:$F$32,0)} -> 紅魔郷 | C5: 6 | D5: {=XLOOKUP(C5,'作品サブタイトル'!$A$2:$A$32,'作品サブタイトル'!$B$2:$B$32,0)} -> 2002 | E5: {=xlookup(C5,'作品サブタイトル'!A$2:A$32,'作品サブタイトル'!E$2:E$32)} -> 1 | F5: 0 | G5: 0 | H5: 2 | N5: 3
A6: チルノ | B6: {=XLOOKUP(C6,'作品サブタイトル'!$A$2:$A$32,'作品サブタイトル'!$F$2:$F$32,0)} -> 紅魔郷 | C6: 6 | D6: {=XLOOKUP(C6,'作品サブタイトル'!$A$2:$A$32,'作品サブタイトル'!$B$2:$B$32,0)} -> 2002 | E6: {=xlookup(C6,'作品サブタイトル'!A$2:A$32,'作品サブタイトル'!E$2:E$32)} -> 1 | F6: 0 | G6: 0 | H6: 2 | J6: 1 | N6: 4
A7: 紅 美鈴 | B7: {=XLOOKUP(C7,'作品サブタイトル'!$A$2:$A$32,'作品サブタイトル'!$F$2:$F$32,0)} -> 紅魔郷 | C7: 6 | D7: {=XLOOKUP(C7,'作品サブタイトル'!$A$2:$A$32,'作品サブタイトル'!$B$2:$B$32,0)} -> 2002 | E7: {=xlookup(C7,'作品サブタイトル'!A$2:A$32,'作品サブタイトル'!E$2:E$32)} -> 1 | F7: 0 | G7: 0 | H7: 3 | N7: 5
A8: 小悪魔 | B8: {=XLOOKUP(C8,'作品サブタイトル'!$A$2:$A$32,'作品サブタイトル'!$F$2:$F$32,0)} -> 紅魔郷 | C8: 6 | D8: {=XLOOKUP(C8,'作品サブタイトル'!$A$2:$A$32,'作品サブタイトル'!$B$2:$B$32,0)} -> 2002 | E8: {=xlookup(C8,'作品サブタイトル'!A$2:A$32,'作品サブタイトル'!E$2:E$32)} -> 1 | F8: 0 | G8: 0 | H8: 4 | N8: 6
A9: パチュリー・ノーレッジ | B9: {=XLOOKUP(C9,'作品サブタイトル'!$A$2:$A$32,'作品サブタイトル'!$F$2:$F$32,0)} -> 紅魔郷 | C9: 6 | D9: {=XLOOKUP(C9,'作品サブタイトル'!$A$2:$A$32,'作品サブタイトル'!$B$2:$B$32,0)} -> 2002 | E9: {=xlookup(C9,'作品サブタイトル'!A$2:A$32,'作品サブタイトル'!E$2:E$32)} -> 1 | F9: 0 | G9: 0 | H9: 4 | N9: 7
A10: 十六夜 咲夜 | B10: {=XLOOKUP(C10,'作品サブタイトル'!$A$2:$A$32,'作品サブタイトル'!$F$2:$F$32,0)} -> 紅魔郷 | C10: 6 | D10: {=XLOOKUP(C10,'作品サブタイトル'!$A$2:$A$32,'作品サブタイトル'!$B$2:$B$32,0)} -> 2002 | E10: {=xlookup(C10,'作品サブタイトル'!A$2:A$32,'作品サブタイトル'!E$2:E$32)} -> 1 | F10: 0 | G10: 0 | H10: 5 | N10: 8
A11: レミリア・スカーレット | B11: {=XLOOKUP(C11,'作品サブタイトル'!$A$2:$A$32,'作品サブタイトル'!$F$2:$F$32,0)} -> 紅魔郷 | C11: 6 | D11: {=XLOOKUP(C11,'作品サブタイトル'!$A$2:$A$32,'作品サブタイトル'!$B$2:$B$32,0)} -> 2002 | E11: {=xlookup(C11,'作品サブタイトル'!A$2:A$32,'作品サブタイトル'!E$2:E$32)} -> 1 | F11: 0 | G11: 0 | H11: 6 | N11: 9
A12: フランドール・スカーレット | B12: {=XLOOKUP(C12,'作品サブタイトル'!$A$2:$A$32,'作品サブタイトル'!$F$2:$F$32,0)} -> 紅魔郷 | C12: 6 | D12: {=XLOOKUP(C12,'作品サブタイトル'!$A$2:$A$32,'作品サブタイトル'!$B$2:$B$32,0)} -> 2002 | E12: {=xlookup(C12,'作品サブタイトル'!A$2:A$32,'作品サブタイトル'!E$2:E$32)} -> 1 | F12: 0 | G12: 0 | H12: 7 | N12: 10
A13: レティ・ホワイトロック | B13: {=XLOOKUP(C13,'作品サブタイトル'!$A$2:$A$32,'作品サブタイトル'!$F$2:$F$32,0)} -> 妖々夢 | C13: 7 | D13: {=XLOOKUP(C13,'作品サブタイトル'!$A$2:$A$32,'作品サブタイトル'!$B$2:$B$32,0)} -> 2003 | E13: {=xlookup(C13,'作品サブタイトル'!A$2:A$32,'作品サブタイトル'!E$2:E$32)} -> 2 | F13: 0 | G13: 0 | H13: 1 | N13: 11
A14: 橙 | B14: {=XLOOKUP(C14,'作品サブタイトル'!$A$2:$A$32,'作品サブタイトル'!$F$2:$F$32,0)} -> 妖々夢 | C14: 7 | D14: {=XLOOKUP(C14,'作品サブタイトル'!$A$2:$A$32,'作品サブタイトル'!$B$2:$B$32,0)} -> 2003 | E14: {=xlookup(C14,'作品サブタイトル'!A$2:A$32,'作品サブタイトル'!E$2:E$32)} -> 2 | F14: 0 | G14: 0 | H14: 2 | N14: 12
A15: アリス・マーガトロイド | B15: {=XLOOKUP(C15,'作品サブタイトル'!$A$2:$A$32,'作品サブタイトル'!$F$2:$F$32,0)} -> 怪綺談 | C15: 5 | D15: {=XLOOKUP(C15,'作品サブタイトル'!$A$2:$A$32,'作品サブタイトル'!$B$2:$B$32,0)} -> 1998 | E15: {=xlookup(C15,'作品サブタイトル'!A$2:A$32,'作品サブタイトル'!E$2:E$32)} -> 1 | F15: 0 | G15: 0 | H15: 3 | N15: 13
A16: リリーホワイト | B16: {=XLOOKUP(C16,'作品サブタイトル'!$A$2:$A$32,'作品サブタイトル'!$F$2:$F$32,0)} -> 妖々夢 | C16: 7 | D16: {=XLOOKUP(C16,'作品サブタイトル'!$A$2:$A$32,'作品サブタイトル'!$B$2:$B$32,0)} -> 2003 | E16: {=xlookup(C16,'作品サブタイトル'!A$2:A$32,'作品サブタイトル'!E$2:E$32)} -> 2 | F16: 0 | G16: 0 | H16: 4 | N16: 14
A17: ルナサ・プリズムリバー | B17: {=XLOOKUP(C17,'作品サブタイトル'!$A$2:$A$32,'作品サブタイトル'!$F$2:$F$32,0)} -> 妖々夢 | C17: 7 | D17: {=XLOOKUP(C17,'作品サブタイトル'!$A$2:$A$32,'作品サブタイトル'!$B$2:$B$32,0)} -> 2003 | E17: {=xlookup(C17,'作品サブタイトル'!A$2:A$32,'作品サブタイトル'!E$2:E$32)} -> 2 | F17: 0 | G17: 0 | H17: 4 | N17: 15
A18: メルラン・プリズムリバー | B18: {=XLOOKUP(C18,'作品サブタイトル'!$A$2:$A$32,'作品サブタイトル'!$F$2:$F$32,0)} -> 妖々夢 | C18: 7 | D18: {=XLOOKUP(C18,'作品サブタイトル'!$A$2:$A$32,'作品サブタイトル'!$B$2:$B$32,0)} -> 2003 | E18: {=xlookup(C18,'作品サブタイトル'!A$2:A$32,'作品サブタイトル'!E$2:E$32)} -> 2 | F18: 0 | G18: 0 | H18: 4 | N18: 16
... A32: 伊吹 萃香 | B32: {=XLOOKUP(C32,'作品サブタイトル'!$A$2:$A$32,'作品サブタイトル'!$F$2:$F$32,0)} -> 萃夢想 | C32: 7.5 | D32: {=XLOOKUP(C32,'作品サブタイトル'!$A$2:$A$32,'作品サブタイトル'!$B$2:$B$32,0)} -> 2004 | E32: {=xlookup(C32,'作品サブタイトル'!A$2:A$32,'作品サブタイトル'!E$2:E$32)} -> 3 | F32: 0 | G32: 0 | H32: 0 | N32: 30
A33: 射命丸 文 | B33: {=XLOOKUP(C33,'作品サブタイトル'!$A$2:$A$32,'作品サブタイトル'!$F$2:$F$32,0)} -> 花映塚 | C33: 9 | D33: {=XLOOKUP(C33,'作品サブタイトル'!$A$2:$A$32,'作品サブタイトル'!$B$2:$B$32,0)} -> 2005 | E33: {=xlookup(C33,'作品サブタイトル'!A$2:A$32,'作品サブタイトル'!E$2:E$32)} -> 4 | F33: 0 | G33: 0 | H33: 7 | I33: 1 | J33: 1 | N33: 31
A34: メディスン・メランコリー | B34: {=XLOOKUP(C34,'作品サブタイトル'!$A$2:$A$32,'作品サブタイトル'!$F$2:$F$32,0)} -> 花映塚 | C34: 9 | D34: {=XLOOKUP(C34,'作品サブタイトル'!$A$2:$A$32,'作品サブタイトル'!$B$2:$B$32,0)} -> 2005 | E34: {=xlookup(C34,'作品サブタイトル'!A$2:A$32,'作品サブタイトル'!E$2:E$32)} -> 4 | F34: 0 | G34: 0 | H34: 4 | I34: 1 | N34: 32
A35: 風見 幽香 | B35: {=XLOOKUP(C35,'作品サブタイトル'!$A$2:$A$32,'作品サブタイトル'!$F$2:$F$32,0)} -> 幻想郷 | C35: 4 | D35: {=XLOOKUP(C35,'作品サブタイトル'!$A$2:$A$32,'作品サブタイトル'!$B$2:$B$32,0)} -> 1998 | E35: {=xlookup(C35,'作品サブタイトル'!A$2:A$32,'作品サブタイトル'!E$2:E$32)} -> 1 | F35: 0 | G35: 0 | H35: 8 | I35: 1 | N35: 33
A36: 小野塚 小町 | B36: {=XLOOKUP(C36,'作品サブタイトル'!$A$2:$A$32,'作品サブタイトル'!$F$2:$F$32,0)} -> 花映塚 | C36: 9 | D36: {=XLOOKUP(C36,'作品サブタイトル'!$A$2:$A$32,'作品サブタイトル'!$B$2:$B$32,0)} -> 2005 | E36: {=xlookup(C36,'作品サブタイトル'!A$2:A$32,'作品サブタイトル'!E$2:E$32)} -> 4 | F36: 0 | G36: 0 | H36: 8 | I36: 1 | N36: 34
A37: 四季映姫・ヤマザナドゥ | B37: {=XLOOKUP(C37,'作品サブタイトル'!$A$2:$A$32,'作品サブタイトル'!$F$2:$F$32,0)} -> 花映塚 | C37: 9 | D37: {=XLOOKUP(C37,'作品サブタイトル'!$A$2:$A$32,'作品サブタイトル'!$B$2:$B$32,0)} -> 2005 | E37: {=xlookup(C37,'作品サブタイトル'!A$2:A$32,'作品サブタイトル'!E$2:E$32)} -> 4 | F37: 0 | G37: 0 | H37: 9 | I37: 1 | N37: 35
A38: 秋 静葉 | B38: {=XLOOKUP(C38,'作品サブタイトル'!$A$2:$A$32,'作品サブタイトル'!$F$2:$F$32,0)} -> 風神録 | C38: 10 | D38: {=XLOOKUP(C38,'作品サブタイトル'!$A$2:$A$32,'作品サブタイトル'!$B$2:$B$32,0)} -> 2007 | E38: {=xlookup(C38,'作品サブタイトル'!A$2:A$32,'作品サブタイトル'!E$2:E$32)} -> 5 | F38: 0 | G38: 0 | H38: 1 | N38: 36
A39: 秋 穣子 | B39: {=XLOOKUP(C39,'作品サブタイトル'!$A$2:$A$32,'作品サブタイトル'!$F$2:$F$32,0)} -> 風神録 | C39: 10 | D39: {=XLOOKUP(C39,'作品サブタイトル'!$A$2:$A$32,'作品サブタイトル'!$B$2:$B$32,0)} -> 2007 | E39: {=xlookup(C39,'作品サブタイトル'!A$2:A$32,'作品サブタイトル'!E$2:E$32)} -> 5 | F39: 0 | G39: 0 | H39: 1 | N39: 37
A40: 鍵山 雛 | B40: {=XLOOKUP(C40,'作品サブタイトル'!$A$2:$A$32,'作品サブタイトル'!$F$2:$F$32,0)} -> 風神録 | C40: 10 | D40: {=XLOOKUP(C40,'作品サブタイトル'!$A$2:$A$32,'作品サブタイトル'!$B$2:$B$32,0)} -> 2007 | E40: {=xlookup(C40,'作品サブタイトル'!A$2:A$32,'作品サブタイトル'!E$2:E$32)} -> 5 | F40: 0 | G40: 0 | H40: 2 | N40: 38
A41: 河城 にとり | B41: {=XLOOKUP(C41,'作品サブタイトル'!$A$2:$A$32,'作品サブタイトル'!$F$2:$F$32,0)} -> 風神録 | C41: 10 | D41: {=XLOOKUP(C41,'作品サブタイトル'!$A$2:$A$32,'作品サブタイトル'!$B$2:$B$32,0)} -> 2007 | E41: {=xlookup(C41,'作品サブタイトル'!A$2:A$32,'作品サブタイトル'!E$2:E$32)} -> 5 | F41: 0 | G41: 0 | H41: 3 | N41: 39
A42: 犬走 椛 | B42: {=XLOOKUP(C42,'作品サブタイトル'!$A$2:$A$32,'作品サブタイトル'!$F$2:$F$32,0)} -> 風神録 | C42: 10 | D42: {=XLOOKUP(C42,'作品サブタイトル'!$A$2:$A$32,'作品サブタイトル'!$B$2:$B$32,0)} -> 2007 | E42: {=xlookup(C42,'作品サブタイトル'!A$2:A$32,'作品サブタイトル'!E$2:E$32)} -> 5 | F42: 0 | G42: 0 | H42: 4 | N42: 40
A43: 東風谷 早苗 | B43: {=XLOOKUP(C43,'作品サブタイトル'!$A$2:$A$32,'作品サブタイトル'!$F$2:$F$32,0)} -> 風神録 | C43: 10 | D43: {=XLOOKUP(C43,'作品サブタイトル'!$A$2:$A$32,'作品サブタイトル'!$B$2:$B$32,0)} -> 2007 | E43: {=xlookup(C43,'作品サブタイトル'!A$2:A$32,'作品サブタイトル'!E$2:E$32)} -> 5 | F43: 0 | G43: 0 | H43: 5 | N43: 41
A44: 八坂 神奈子 | B44: {=XLOOKUP(C44,'作品サブタイトル'!$A$2:$A$32,'作品サブタイトル'!$F$2:$F$32,0)} -> 風神録 | C44: 10 | D44: {=XLOOKUP(C44,'作品サブタイトル'!$A$2:$A$32,'作品サブタイトル'!$B$2:$B$32,0)} -> 2007 | E44: {=xlookup(C44,'作品サブタイトル'!A$2:A$32,'作品サブタイトル'!E$2:E$32)} -> 5 | F44: 0 | G44: 0 | H44: 6 | N44: 42
A45: 洩矢 諏訪子 | B45: {=XLOOKUP(C45,'作品サブタイトル'!$A$2:$A$32,'作品サブタイトル'!$F$2:$F$32,0)} -> 風神録 | C45: 10 | D45: {=XLOOKUP(C45,'作品サブタイトル'!$A$2:$A$32,'作品サブタイトル'!$B$2:$B$32,0)} -> 2007 | E45: {=xlookup(C45,'作品サブタイトル'!A$2:A$32,'作品サブタイトル'!E$2:E$32)} -> 5 | F45: 0 | G45: 0 | H45: 7 | N45: 43
A46: 永江 衣玖 | B46: {=XLOOKUP(C46,'作品サブタイトル'!$A$2:$A$32,'作品サブタイトル'!$F$2:$F$32,0)} -> 緋想天 | C46: 10.5 | D46: {=XLOOKUP(C46,'作品サブタイトル'!$A$2:$A$32,'作品サブタイトル'!$B$2:$B$32,0)} -> 2008 | E46: {=xlookup(C46,'作品サブタイトル'!A$2:A$32,'作品サブタイトル'!E$2:E$32)} -> 5 | F46: 0 | G46: 0 | H46: 0 | J46: 1 | N46: 44
A47: 比那名居 天子 | B47: {=XLOOKUP(C47,'作品サブタイトル'!$A$2:$A$32,'作品サブタイトル'!$F$2:$F$32,0)} -> 緋想天 | C47: 10.5 | D47: {=XLOOKUP(C47,'作品サブタイトル'!$A$2:$A$32,'作品サブタイトル'!$B$2:$B$32,0)} -> 2008 | E47: {=xlookup(C47,'作品サブタイトル'!A$2:A$32,'作品サブタイトル'!E$2:E$32)} -> 5 | F47: 0 | G47: 0 | H47: 0 | J47: 1 | N47: 45
A48: キスメ | B48: {=XLOOKUP(C48,'作品サブタイトル'!$A$2:$A$32,'作品サブタイトル'!$F$2:$F$32,0)} -> 地霊殿 | C48: 11 | D48: {=XLOOKUP(C48,'作品サブタイトル'!$A$2:$A$32,'作品サブタイトル'!$B$2:$B$32,0)} -> 2008 | E48: {=xlookup(C48,'作品サブタイトル'!A$2:A$32,'作品サブタイトル'!E$2:E$32)} -> 5 | F48: 0 | G48: 0 | H48: 1 | N48: 46
A49: 黒谷 ヤマメ | B49: {=XLOOKUP(C49,'作品サブタイトル'!$A$2:$A$32,'作品サブタイトル'!$F$2:$F$32,0)} -> 地霊殿 | C49: 11 | D49: {=XLOOKUP(C49,'作品サブタイトル'!$A$2:$A$32,'作品サブタイトル'!$B$2:$B$32,0)} -> 2008 | E49: {=xlookup(C49,'作品サブタイトル'!A$2:A$32,'作品サブタイトル'!E$2:E$32)} -> 5 | F49: 0 | G49: 0 | H49: 1 | N49: 47
A50: 水橋 パルスィ | B50: {=XLOOKUP(C50,'作品サブタイトル'!$A$2:$A$32,'作品サブタイトル'!$F$2:$F$32,0)} -> 地霊殿 | C50: 11 | D50: {=XLOOKUP(C50,'作品サブタイトル'!$A$2:$A$32,'作品サブタイトル'!$B$2:$B$32,0)} -> 2008 | E50: {=xlookup(C50,'作品サブタイトル'!A$2:A$32,'作品サブタイトル'!E$2:E$32)} -> 5 | F50: 0 | G50: 0 | H50: 2 | N50: 48
A51: 星熊 勇儀 | B51: {=XLOOKUP(C51,'作品サブタイトル'!$A$2:$A$32,'作品サブタイトル'!$F$2:$F$32,0)} -> 地霊殿 | C51: 11 | D51: {=XLOOKUP(C51,'作品サブタイトル'!$A$2:$A$32,'作品サブタイトル'!$B$2:$B$32,0)} -> 2008 | E51: {=xlookup(C51,'作品サブタイトル'!A$2:A$32,'作品サブタイトル'!E$2:E$32)} -> 5 | F51: 0 | G51: 0 | H51: 3 | N51: 49
A52: 古明地 さとり | B52: {=XLOOKUP(C52,'作品サブタイトル'!$A$2:$A$32,'作品サブタイトル'!$F$2:$F$32,0)} -> 地霊殿 | C52: 11 | D52: {=XLOOKUP(C52,'作品サブタイトル'!$A$2:$A$32,'作品サブタイトル'!$B$2:$B$32,0)} -> 2008 | E52: {=xlookup(C52,'作品サブタイトル'!A$2:A$32,'作品サブタイトル'!E$2:E$32)} -> 5 | F52: 0 | G52: 0 | H52: 4 | N52: 50
A53: 火焔猫 燐 | B53: {=XLOOKUP(C53,'作品サブタイトル'!$A$2:$A$32,'作品サブタイトル'!$F$2:$F$32,0)} -> 地霊殿 | C53: 11 | D53: {=XLOOKUP(C53,'作品サブタイトル'!$A$2:$A$32,'作品サブタイトル'!$B$2:$B$32,0)} -> 2008 | E53: {=xlookup(C53,'作品サブタイトル'!A$2:A$32,'作品サブタイトル'!E$2:E$32)} -> 5 | F53: 0 | G53: 0 | H53: 5 | N53: 51
...

Sheet 作品サブタイトル
A1: 番号 | B1: 年 | C1: 月 | D1: 人気投票月 | E1: 人気投票初出 | F1: サブタイトル | G1: サブタイトル
A2: 1 | B2: 1996 | C2: 11 | E2: 1 | F2: 靈異伝
A3: 2 | B3: 1997 | C3: 8 | E3: 1 | F3: 封魔録
A4: 3 | B4: 1997 | C4: 12 | E4: 1 | F4: 夢時空
A5: 4 | B5: 1998 | C5: 8 | E5: 1 | F5: 幻想郷
A6: 5 | B6: 1998 | C6: 8 | E6: 1 | F6: 怪綺談
A7: 6 | B7: 2002 | C7: 8 | E7: 1 | F7: 紅魔郷
A8: 7 | B8: 2003 | C8: 8 | E8: 2 | F8: 妖々夢
A9: 8 | B9: 2004 | C9: 8 | E9: 2 | F9: 永夜抄
A10: 7.5 | B10: 2004 | C10: 12 | E10: 3 | F10: 萃夢想
A11: 9 | B11: 2005 | C11: 8 | E11: 4 | F11: 花映塚
A12: 9.5 | B12: 2005 | C12: 12 | D12: 12 | E12: 5 | F12: 文花帖
A13: 10 | B13: 2007 | C13: 8 | E13: 5 | F13: 風神録
A14: 10.5 | B14: 2008 | C14: 5 | D14: 2 | E14: 5 | F14: 緋想天
A15: 11 | B15: 2008 | C15: 8 | D15: 2 | E15: 5 | F15: 地霊殿
A16: 12 | B16: 2009 | C16: 8 | D16: 1 | E16: 6 | F16: 星蓮船
A17: 12.3 | B17: 2009 | C17: 8 | D17: 1 | E17: 6 | F17: 非想天則
A18: 12.5 | B18: 2010 | C18: 3 | D18: 2 | E18: 7 | F18: ダブルスポイラー
A19: 12.8 | B19: 2010 | C19: 8 | D19: 2 | E19: 7 | F19: 妖精大戦争
A20: 13 | B20: 2011 | C20: 8 | D20: 2 | E20: 8 | F20: 神霊廟
A21: 13.5 | B21: 2013 | C21: 5 | E21: 9 | F21: 心綺楼
A22: 14 | B22: 2013 | C22: 8 | E22: 9 | F22: 輝針城
A23: 14.3 | B23: 2014 | C23: 5 | D23: 2 | E23: 10 | F23: 天邪鬼
A24: 14.5 | B24: 2015 | C24: 5 | D24: 5 | E24: 11 | F24: 深秘録
A25: 15 | B25: 2015 | C25: 8 | D25: 5 | E25: 11 | F25: 紺珠伝
A26: 16 | B26: 2017 | C26: 8 | D26: 1 | E26: 13 | F26: 天空璋
A27: 15.5 | B27: 2017 | C27: 12 | D27: 1 | E27: 13 | F27: 憑依華
A28: 16.5 | B28: 2018 | C28: 8 | D28: 1 | E28: 14 | F28: 秘封ナイトメアダイアリー
A29: 17 | B29: 2019 | C29: 8 | D29: 1 | E29: 15 | F29: 鬼形獣
A30: 18 | B30: 2021 | C30: 5 | D30: 6 | E30: 16 | F30: 虹龍洞
A31: 17.5 | B31: 2021 | C31: 10 | D31: 10 | E31: 16 | F31: 剛欲異聞
A32: 18.5 | B32: 2022 | C32: 8 | D32: 9 | E32: 18 | F32: バレットフィリア達の闇市場

Sheet 人気投票総数
A1: 第 | B1: 年 | C1: キャラ | D1: 音楽 | E1: 作品
A2: 1 | B2: 2002 | C2: 544 | D2: 678
A3: 2 | B3: 2003 | C3: 1195 | D3: 945 | E3: 711 | F3: 728
A4: 3 | B4: 2004 | C4: 4942 | D4: 2636 | F4: 3525 | G4: 2894
A5: 4 | B5: 2005 | C5: 4426 | D5: 3801 | E5: 2997
A6: spell | B6: 2006 | C6: 1602
A7: 5 | B7: 2008 | C7: 12220 | D7: 10787 | E7: 8501
A8: 6 | B8: 2009 | C8: 22087 | D8: 18774 | E8: 15156
A9: 7 | B9: 2010 | C9: 33449 | D9: 28110 | E9: 22245
A10: 8 | B10: 2011 | C10: 35946 | D10: 29285 | E10: 21499
A11: 9 | B11: 2012 | C11: 43737 | D11: 32842 | E11: 20105
A12: 10 | B12: 2014 | C12: 31040 | D12: 23283 | E12: 15494
A13: 11 | B13: 2015 | C13: 32244 | D13: 20843 | E13: 10636
A14: 12 | B14: 2016 | C14: 42419 | D14: 32356 | E14: 24742 | F14: 18268
A15: 13 | B15: 2017 | C15: 36727 | D15: 27694 | E15: 21222 | F15: 24241 | G15: 16845
A16: 14 | B16: 2018 | C16: 32065 | D16: 23648 | E16: 18470
A17: 15 | B17: 2019 | C17: 23883 | D17: 17951 | E17: 13946
A18: 16 | B18: 2020 | C18: 34573 | D18: 25919 | E18: 19274
A19: 16ex | B19: 2021 | C19: 10849
A20: 17 | B20: 2021 | C20: 40363 | D20: 30104 | E20: 23047
A21: 18 | B21: 2022 | C21: 51652 | D21: 37659 | E21: 28558

Sheet 主人公詰め
A1: 番号 | B1: 1~5 | C1: 6 | D1: 7 | E1: 8 | F1: 7.5 | G1: 9 | H1: 9.5 | I1: 10 | J1: 10.5 | K1: 11 | L1: 12 | M1: 12.3 | N1: 12.5 | O1: 12.8 | P1: 13 | Q1: 13.5 | R1: 14 | S1: 14.3 | T1: 14.5 | U1: 15 | V1: 16 | W1: 15.5 | X1: 16.5 | Y1: 17 | Z1: 18 | AA1: 17.5 | AB1: 18.5
A2: 年 | B2: 2000 | C2: 2002 | D2: 2003 | E2: 2004 | F2: 2004 | G2: 2005 | H2: 2005 | I2: 2007 | J2: 2008 | K2: 2008 | L2: 2009 | M2: 2009 | N2: 2010 | O2: 2010 | P2: 2011 | Q2: 2013 | R2: 2013 | S2: 2014 | T2: 2015 | U2: 2015 | V2: 2017 | W2: 2017 | X2: 2018 | Y2: 2019 | Z2: 2021 | AA2: 2021 | AB2: 2022
A3: 人気投票 | B3: 1 | C3: 1 | D3: 2 | E3: 2 | F3: 3 | G3: 4 | H3: 5 | I3: 5 | J3: 5 | K3: 5 | L3: 6 | M3: 6 | N3: 7 | O3: 7 | P3: 8 | Q3: 9 | R3: 9 | S3: 10 | T3: 11 | U3: 11 | V3: 13 | W3: 13 | X3: 14 | Y3: 15 | Z3: 16 | AA3: 16 | AB3: 18
A4: 作品 | B4: 旧作-西方 | C4: 紅魔郷 | D4: 妖々夢 | E4: 永夜抄 | F4: 萃夢想 | G4: 花映塚 | H4: 文花帖 | I4: 風神録 | J4: 緋想天 | K4: 地霊殿 | L4: 星蓮船 | M4: 非想天則 | N4: ダブルスポイラー | O4: 妖精大戦争 | P4: 神霊廟 | Q4: 心綺楼 | R4: 輝針城 | S4: 天邪鬼 | T4: 深秘録 | U4: 紺珠伝 | V4: 天空璋 | W4: 憑依華 | X4: 秘封ナイトメアダイアリー | Y4: 鬼形獣 | Z4: 虹龍洞 | AA4: 剛欲異聞 | AB4: バレットフィリア達の闇市場
B5: 博麗 霊夢 | C5: 博麗 霊夢 | D5: 博麗 霊夢 | E5: 博麗 霊夢 | F5: 博麗 霊夢 | G5: 博麗 霊夢 | H5: 射命丸 文 | I5: 博麗 霊夢 | J5: 博麗 霊夢 | K5: 博麗 霊夢 | L5: 博麗 霊夢 | M5: 博麗 霊夢 | N5: 射命丸 文 | O5: チルノ | P5: 博麗 霊夢 | R5: 博麗 霊夢 | S5: 鬼人 正邪 | U5: 博麗 霊夢 | V5: 博麗 霊夢 | Y5: 博麗 霊夢 | Z5: 博麗 霊夢 | AB5: 霧雨 魔理沙
B6: 霧雨 魔理沙 | C6: 霧雨 魔理沙 | D6: 霧雨 魔理沙 | E6: 霧雨 魔理沙 | F6: 霧雨 魔理沙 | G6: 霧雨 魔理沙 | I6: 霧雨 魔理沙 | J6: 霧雨 魔理沙 | K6: 霧雨 魔理沙 | L6: 霧雨 魔理沙 | M6: 霧雨 魔理沙 | N6: 姫海棠 はたて | P6: 霧雨 魔理沙 | R6: 霧雨 魔理沙 | U6: 霧雨 魔理沙 | V6: 霧雨 魔理沙 | Y6: 霧雨 魔理沙 | Z6: 霧雨 魔理沙
D7: 十六夜 咲夜 | E7: 十六夜 咲夜 | J7: 十六夜 咲夜 | L7: 東風谷 早苗 | P7: 魂魄 妖夢 | R7: 十六夜 咲夜 | U7: 鈴仙・優曇華院・イナバ | V7: チルノ | Y7: 魂魄 妖夢 | Z7: 十六夜 咲夜
E8: 魂魄 妖夢 | J8: アリス・マーガトロイド | P8: 東風谷 早苗 | U8: 東風谷 早苗 | Z8: 東風谷 早苗
J9: パチュリー・ノーレッジ
J10: 魂魄 妖夢
J11: レミリア・スカーレット
J12: 西行寺 幽々子
J13: 八雲 紫
J14: 伊吹 萃香
J15: 鈴仙・優曇華院・イナバ
J16: 射命丸 文
J17: 小野塚 小町
J18: 永江 衣玖
J19: 比那名居 天子

Sheet 整数詰め
A1: 番号 | B1: 1~5 | C1: 6 | D1: 7 | E1: 8 | F1: 9 | G1: 10 | H1: 11 | I1: 12 | J1: 13 | K1: 14 | L1: 15 | M1: 16 | N1: 17 | O1: 18
A2: 年 | B2: 2000 | C2: 2002 | D2: 2003 | E2: 2004 | F2: 2005 | G2: 2007 | H2: 2008 | I2: 2009 | J2: 2011 | K2: 2013 | L2: 2015 | M2: 2017 | N2: 2019 | O2: 2021
A3: 人気投票 | B3: 1 | C3: 1 | D3: 2 | E3: 2 | F3: 4 | G3: 5 | H3: 5 | I3: 6 | J3: 8 | K3: 9 | L3: 11 | M3: 13 | N3: 15 | O3: 16
A4: 作品 | B4: 旧作-西方 | C4: 紅魔郷 | D4: 妖々夢 | E4: 永夜抄 | F4: 花映塚 | G4: 風神録 | H4: 地霊殿 | I4: 星蓮船 | J4: 神霊廟 | K4: 輝針城 | L4: 紺珠伝 | M4: 天空璋 | N4: 鬼形獣 | O4: 虹龍洞
B5: 博麗 霊夢 | C5: 博麗 霊夢 | D5: 博麗 霊夢 | E5: 博麗 霊夢 | F5: 博麗 霊夢 | G5: 博麗 霊夢 | H5: 博麗 霊夢 | I5: 博麗 霊夢 | J5: 博麗 霊夢 | K5: 博麗 霊夢 | L5: 博麗 霊夢 | M5: 博麗 霊夢 | N5: 博麗 霊夢 | O5: 博麗 霊夢
B6: 霧雨 魔理沙 | C6: 霧雨 魔理沙 | D6: 霧雨 魔理沙 | E6: 霧雨 魔理沙 | F6: 霧雨 魔理沙 | G6: 霧雨 魔理沙 | H6: 霧雨 魔理沙 | I6: 霧雨 魔理沙 | J6: 霧雨 魔理沙 | K6: 霧雨 魔理沙 | L6: 霧雨 魔理沙 | M6: 霧雨 魔理沙 | N6: 霧雨 魔理沙 | O6: 霧雨 魔理沙
D7: 十六夜 咲夜 | E7: 十六夜 咲夜 | I7: 東風谷 早苗 | J7: 魂魄 妖夢 | K7: 十六夜 咲夜 | L7: 鈴仙・優曇華院・イナバ | M7: チルノ | N7: 魂魄 妖夢 | O7: 十六夜 咲夜
E8: 魂魄 妖夢 | J8: 東風谷 早苗 | L8: 東風谷 早苗 | O8: 東風谷 早苗

Sheet 非整数詰め
A1: 番号 | B1: 7.5 | C1: 9.5 | D1: 10.5 | E1: 12.3 | F1: 12.5 | G1: 12.8 | H1: 13.5 | I1: 14.3 | J1: 14.5 | K1: 15.5 | L1: 16.5 | M1: 17.5 | N1: 18.5
A2: 年 | B2: 2004 | C2: 2005 | D2: 2008 | E2: 2009 | F2: 2010 | G2: 2010 | H2: 2013 | I2: 2014 | J2: 2015 | K2: 2017 | L2: 2018 | M2: 2021 | N2: 2022
A3: 人気投票 | B3: 3 | C3: 5 | D3: 5 | E3: 6 | F3: 7 | G3: 7 | H3: 9 | I3: 10 | J3: 11 | K3: 13 | L3: 14 | M3: 16 | N3: 18
A4: 作品 | B4: 萃夢想 | C4: 文花帖 | D4: 緋想天 | E4: 非想天則 | F4: ダブルスポイラー | G4: 妖精大戦争 | H4: 心綺楼 | I4: 天邪鬼 | J4: 深秘録 | K4: 憑依華 | L4: 秘封ナイトメアダイアリー | M4: 剛欲異聞 | N4: バレットフィリア達の闇市場
B5: 博麗霊夢 | C5: 射命丸文 | D5: 博麗 霊夢 | E5: 東風谷 早苗 | F5: 秋静葉 | G5: チルノ | H5: 博麗 霊夢 | I5: 鬼人 正邪 | J5: 博麗霊夢 | K5: 博麗霊夢 | L5: 宇佐見 菫子 | M5: 饕餮 尤魔 | N5: 霧雨 魔理沙
B6: 霧雨魔理沙 | C6: ルーミア | D6: 霧雨 魔理沙 | E6: チルノ | F6: 鍵山雛 | G6: リリーホワイト | H6: 霧雨 魔理沙 | I6: チルノ | J6: 霧雨魔理沙 | K6: 霧雨魔理沙 | L6: 博麗 霊夢 | M6: 博麗 霊夢 | N6: 豪徳寺ミケ
B7: 十六夜咲夜 | C7: リグル・ナイトバグ | D7: 十六夜 咲夜 | E7: 紅 美鈴 | F7: キスメ | G7: 大妖精 | H7: 雲居 一輪 | I7: わかさぎ姫 | J7: 雲居一輪 | K7: 雲居一輪 | L7: 清蘭 | M7: 霧雨 魔理沙 | N7: チルノ
B8: アリス・マーガトロイド | C8: チルノ | D8: アリス・マーガトロイド | E8: 霊烏路 空 | F8: 多々良小傘 | G8: サニーミルク | H8: 聖 白蓮 | I8: 赤蛮奇 | J8: 聖白蓮 | K8: 聖白蓮 | L8: 鈴瑚 | M8: 八坂神奈子 | N8: 戎瓔花
B9: パチュリー・ノーレッジ | C9: アリス・マーガトロイド | D9: パチュリー・ノーレッジ | E9: 洩矢 諏訪子 | F9: 犬走椛 | G9: ルナチャイルド | H9: 物部 布都 | I9: 上白沢慧音 | J9: 物部布都 | K9: 物部布都 | L9: エタニティラルバ | M9: 村紗水蜜 | N9: 東風谷早苗
B10: 魂魄妖夢 | C10: 鈴仙・優曇華院・イナバ | D10: 魂魄 妖夢 | E10: 博麗 霊夢 | F10: 村紗水蜜 | G10: スターサファイア | H10: 豊聡 耳神子 | I10: 霍青娥 | J10: 豊聡耳神子 | K10: 豊聡耳神子 | L10: 霧雨 魔理沙 | M10: 依神 女苑 | N10: 菅牧典
B11: レミリア・スカーレット | C11: 紅美鈴 | D11: レミリア・スカーレット | E11: 霧雨 魔理沙 | F11: 伊吹萃香 | G11: 霧雨 魔理沙 | H11: 河城 にとり | I11: 九十九八橋 | J11: 河城にとり | K11: 河城にとり | L11: 矢田寺成美 | M11: 依神 紫苑 | N11: 伊吹萃香
B12: 西行寺幽々子 | C12: 橙 | D12: 西行寺 幽々子 | E12: アリス・マーガトロイド | F12: ナズーリン | H12: 古明地 こいし | I12: 射命丸文 | J12: 古明地こいし | K12: 古明地こいし | L12: 坂田ネムノ | M12: フランドール・スカーレット | N12: 天弓千亦
B13: 八雲紫 | C13: 十六夜咲夜 | D13: 八雲 紫 | E13: パチュリー・ノーレッジ | F13: 霊烏路空 | H13: 二ッ岩 マミゾウ | I13: 十六夜咲夜 | J13: 二ッ岩マミゾウ | K13: 二ッ岩マミゾウ | L13: 高麗野あうん | M13: 多々良小傘 | N13: 秋穣子
B14: 伊吹萃香 | C14: 八雲藍 | D14: 伊吹 萃香 | F14: 古明地こいし | H14: 秦 こころ | I14: 博麗霊夢 | J14: 秦こころ | K14: 秦こころ | L14: クラウンピース | M14: 星熊勇儀 | N14: わかさぎ姫
B15: 紅美鈴 | C15: 八意永琳 | D15: 鈴仙・優曇華院・イナバ | F15: 永江衣玖 | I15: 洩矢諏訪子 | J15: 茨木華扇 | K15: 茨木華扇 | L15: 稀神サグメ | M15: 黒谷ヤマメ | N15: 庭渡久侘歌
C16: 小野塚小町 | D16: 射命丸 文 | F16: 洩矢諏訪子 | I16: 豊聡耳神子 | J16: 藤原妹紅 | K16: 藤原妹紅 | L16: 丁礼田舞 | M16: 霊烏路空 | N16: 十六夜咲夜
C17: フランドール・スカーレット | D17: 小野塚 小町 | F17: 封獣ぬえ | I17: 藤原妹紅 | J17: 少名針妙丸 | K17: 少名針妙丸 | L17: 爾子田里乃 | M17: 庭渡久侘歌 | N17: 飯綱丸龍
C18: レティ・ホワイトロック | D18: 永江 衣玖 | F18: 霧雨魔理沙 | I18: 宮古芳香 | J18: 宇佐見菫子 | K18: 宇佐見菫子 | L18: ドレミー・スイート | M18: 摩多羅隠岐奈 | N18: 二ッ岩マミゾウ
C19: 上白沢慧音 | D19: 比那名居 天子 | F19: 東風谷早苗 | I19: 九十九弁々 | J19: 鈴仙・優曇華院・イナバ | K19: 鈴仙・優曇華院・イナバ | L19: ヘカーティア・ラピスラズリ | N19: エタニティラルバ
C20: 因幡てゐ | F20: 射命丸文 | I20: 河城にとり | K20: ドレミー・スイート | L20: 純狐 | N20: 牛崎潤美
C21: パチュリー・ノーレッジ | F21: 秋穣子 | I21: 犬走椛 | K21: 比那名居天子 | L21: 摩多羅隠岐奈 | N21: 矢田寺成美
C22: 魂魄妖夢 | F22: 水橋パルスィ | I22: 東風谷早苗 | K22: 八雲紫 | L22: レミリア・スカーレット | N22: 魂魄妖夢
C23: レミリア・スカーレット | F23: 黒谷ヤマメ | I23: 姫海棠はたて | K23: 依神 女苑 | L23: フランドール・スカーレット | N23: クラウンピース
C24: 西行寺幽々子 | F24: 河城にとり | I24: 魂魄妖夢 | K24: 依神 紫苑 | L24: 聖白蓮 | N24: 驪駒早鬼
C25: 蓬莱山輝夜 | F25: 雲居一輪 | I25: 二ッ岩マミゾウ | L25: 豊聡耳神子 | N25: 坂田ネムノ
C26: 四季映姫・ヤマザナドゥ | F26: 星熊勇儀 | I26: 物部布都 | L26: 西行寺幽々子 | N26: 赤蛮奇
C27: 八雲紫 | F27: 寅丸星 | I27: 比那名居天子 | L27: 四季映姫・ヤマザナドゥ | N27: 小野塚小町
C28: メディスン・メランコリー | F28: 火焔猫 燐 | I28: 九十九八橋 | L28: 八意永琳 | N28: 博麗霊夢
C29: 藤原妹紅 | F29: 古明地さとり | I29: 幽谷響子 | L29: 古明地さとり | N29: 比那名居天子
C30: 伊吹萃香 | F30: 比那名居天子 | I30: 今泉影狼 | L30: 二ッ岩マミゾウ | N30: 姫虫百々世
F31: 八坂神奈子 | I31: 西行寺幽々子 | L31: 伊吹萃香 | N31: 河城にとり
F32: 聖白蓮 | I32: 堀川雷鼓 | L32: 摩多羅隠岐奈 | N32: 山城たかね
F33: 博麗霊夢 | I33: 二ッ岩マミゾウ | L33: ドレミー・スイート
F34: 姫海棠はたて | I34: 霧雨魔理沙 | L34: 蓬莱山輝夜
I35: 少名針妙丸 | L35: 霊烏路空
I36: 八坂神奈子 | L36: 封獣ぬえ
I37: 聖白蓮 | L37: 藤原妹紅
I38: 伊吹萃香 | L38: 八雲紫
I39: レミリア・スカーレット | L39: 八坂神奈子
I40: 八雲紫 | L40: 比那名居天子
...

Sheet 年回数作品対応
A1: 番号 | B1: 年 | C1: 人気投票 | D1: 作品
A2: 1~5 | B2: 2000 | C2: 1 | D2: 旧作-西方
A3: 6 | B3: 2002 | C3: 1 | D3: 紅魔郷
A4: 7 | B4: 2003 | C4: 2 | D4: 妖々夢
A5: 8 | B5: 2004 | C5: 2 | D5: 永夜抄
A6: 9 | B6: 2005 | C6: 4 | D6: 花映塚
A7: 10 | B7: 2007 | C7: 5 | D7: 風神録
A8: 11 | B8: 2008 | C8: 5 | D8: 地霊殿
A9: 12 | B9: 2009 | C9: 6 | D9: 星蓮船
A10: 13 | B10: 2011 | C10: 8 | D10: 神霊廟
A11: 14 | B11: 2013 | C11: 9 | D11: 輝針城
A12: 15 | B12: 2015 | C12: 11 | D12: 紺珠伝
A13: 16 | B13: 2017 | C13: 13 | D13: 天空璋
A14: 17 | B14: 2019 | C14: 15 | D14: 鬼形獣
A15: 18 | B15: 2021 | C15: 16 | D15: 虹龍洞

Sheet 年回数非整数作品対応
A1: 番号 | B1: 年 | C1: 人気投票 | D1: 作品
A2: 7.5 | B2: 2004 | C2: 3 | D2: 萃夢想
A3: 9.5 | B3: 2005 | C3: 5 | D3: 文花帖
A4: 10.5 | B4: 2008 | C4: 5 | D4: 緋想天
A5: 12.3 | B5: 2009 | C5: 6 | D5: 非想天則
A6: 12.5 | B6: 2010 | C6: 7 | D6: ダブルスポイラー
A7: 12.8 | B7: 2010 | C7: 7 | D7: 妖精大戦争
A8: 13.5 | B8: 2013 | C8: 9 | D8: 心綺楼
A9: 14.3 | B9: 2014 | C9: 10 | D9: 天邪鬼
A10: 14.5 | B10: 2015 | C10: 11 | D10: 深秘録
A11: 15.5 | B11: 2017 | C11: 13 | D11: 憑依華
A12: 16.5 | B12: 2018 | C12: 14 | D12: 秘封ナイトメアダイアリー
A13: 17.5 | B13: 2021 | C13: 16 | D13: 剛欲異聞
A14: 18.5 | B14: 2022 | C14: 18 | D14: バレットフィリア達の闇市場

Sheet アンケート年齢
A2: 回 | C2: 18 | D2: 18 | E2: 17 | F2: 17 | G2: 16 | H2: 16 | I2: 15 | J2: 15 | K2: 14 | L2: 14 | M2: 13 | N2: 13 | O2: 12 | P2: 12 | Q2: 11 | R2: 11 | S2: 10 | T2: 10 | U2: 9 | V2: 9 | W2: 8 | X2: 8 | Y2: 7 | Z2: 7
A3: 〜9歳 | B3: 7 | C3: 36 | D3: 0.0024 | E3: 17 | F3: 0.0015 | G3: 14 | H3: 0.001 | I3: 17 | J3: 0.0017 | K3: 14 | L3: 0.0011 | M3: 16 | N3: 0.0011 | O3: 19 | P3: 0.0011 | Q3: 11 | R3: 0.0011 | S3: 14 | T3: 0.001 | U3: 25 | V3: 0.0014 | W3: 20 | X3: 0.001 | Y3: 23 | Z3: 0.0012
A4: 10〜14歳 | B4: 12 | C4: 2314 | D4: 0.1529 | E4: 1199 | F4: 0.1053 | G4: 998 | H4: 0.0746 | I4: 569 | J4: 0.056 | K4: 761 | L4: 0.0583 | M4: 999 | N4: 0.0661 | O4: 1171 | P4: 0.0694 | Q4: 556 | R4: 0.0575 | S4: 600 | T4: 0.044 | U4: 555 | V4: 0.0305 | W4: 712 | X4: 0.0369 | Y4: 730 | Z4: 0.0372
A5: 15〜19歳 | B5: 17 | C5: 5939 | D5: 0.3924 | E5: 4393 | F5: 0.3859 | G5: 5038 | H5: 0.3768 | I5: 3486 | J5: 0.343 | K5: 4560 | L5: 0.3492 | M5: 5489 | N5: 0.3631 | O5: 6656 | P5: 0.3946 | Q5: 3425 | R5: 0.3544 | S5: 4430 | T5: 0.3249 | U5: 5843 | V5: 0.3209 | W5: 6525 | X5: 0.3386 | Y5: 6655 | Z5: 0.3391
A6: 20〜24歳 | B6: 22 | C6: 3343 | D6: 0.2209 | E6: 2718 | F6: 0.2388 | G6: 3546 | H6: 0.2652 | I6: 2860 | J6: 0.2814 | K6: 3850 | L6: 0.2948 | M6: 4399 | N6: 0.291 | O6: 4663 | P6: 0.2764 | Q6: 2763 | R6: 0.2859 | S6: 4372 | T6: 0.3206 | U6: 6562 | V6: 0.3604 | W6: 7072 | X6: 0.3669 | Y6: 7649 | Z6: 0.3898
A7: 25〜29歳 | B7: 27 | C7: 1711 | D7: 0.113 | E7: 1509 | F7: 0.1326 | G7: 1946 | H7: 0.1455 | I7: 1605 | J7: 0.1579 | K7: 2024 | L7: 0.155 | M7: 2256 | N7: 0.1492 | O7: 2485 | P7: 0.1473 | Q7: 1657 | R7: 0.1715 | S7: 2570 | T7: 0.1885 | U7: 3406 | V7: 0.187 | W7: 3314 | X7: 0.172 | Y7: 3138 | Z7: 0.1599
A8: 30〜34歳 | B8: 32 | C8: 912 | D8: 0.0603 | E8: 821 | F8: 0.0721 | G8: 1013 | H8: 0.0758 | I8: 908 | J8: 0.0893 | K8: 1077 | L8: 0.0825 | M8: 1173 | N8: 0.0776 | O8: 1164 | P8: 0.069 | Q8: 778 | R8: 0.0805 | S8: 1052 | T8: 0.0771 | U8: 1219 | V8: 0.0669 | W8: 1132 | X8: 0.0587 | Y8: 1028 | Z8: 0.0524
A9: 35〜39歳 | B9: 37 | C9: 469 | D9: 0.031 | E9: 389 | F9: 0.0342 | G9: 468 | H9: 0.035 | I9: 422 | J9: 0.0415 | K9: 480 | L9: 0.0368 | M9: 480 | N9: 0.0318 | O9: 464 | P9: 0.0275 | Q9: 310 | R9: 0.0321 | S9: 410 | T9: 0.0301 | U9: 437 | V9: 0.024 | W9: 380 | X9: 0.0197 | Y9: 316 | Z9: 0.0161
A10: 40〜44歳 | B10: 42 | C10: 223 | D10: 0.0147 | E10: 191 | F10: 0.0168 | G10: 219 | H10: 0.0164 | I10: 189 | J10: 0.0186 | K10: 188 | L10: 0.0144 | M10: 197 | N10: 0.013 | O10: 149 | P10: 0.0088 | Q10: 109 | R10: 0.0113 | S10: 163 | T10: 0.012 | U10: 129 | V10: 0.0071 | W10: 89 | X10: 0.0046 | Y10: 55 | Z10: 0.0028
A11: 45〜49歳 | B11: 47 | C11: 100 | D11: 0.0066 | E11: 87 | F11: 0.0076 | G11: 82 | H11: 0.0061 | I11: 71 | J11: 0.007 | K11: 67 | L11: 0.0051 | M11: 51 | N11: 0.0034 | O11: 47 | P11: 0.0028 | Q11: 29 | R11: 0.003 | S11: 10 | T11: 0.0007 | U11: 14 | V11: 0.0008 | W11: 2 | X11: 0.0001 | Y11: 5 | Z11: 0.0003
A12: 50歳〜 | B12: 52 | C12: 88 | D12: 0.0058 | E12: 60 | F12: 0.0053 | G12: 46 | H12: 0.0034 | I12: 36 | J12: 0.0035 | K12: 39 | L12: 0.003 | M12: 58 | N12: 0.0038 | O12: 51 | P12: 0.003 | Q12: 26 | R12: 0.0027 | S12: 15 | T12: 0.0011 | U12: 20 | V12: 0.0011 | W12: 27 | X12: 0.0014 | Y12: 25 | Z12: 0.0013
A13: 合計数 | C13: =sum(C3:C12) -> 15135 | E13: =sum(E3:E12) -> 11384 | G13: =sum(G3:G12) -> 13370 | I13: =sum(I3:I12) -> 10163 | K13: =sum(K3:K12) -> 13060 | M13: =sum(M3:M12) -> 15118 | O13: =sum(O3:O12) -> 16869 | Q13: =sum(Q3:Q12) -> 9664 | S13: =sum(S3:S12) -> 13636 | U13: =sum(U3:U12) -> 18210 | W13: =sum(W3:W12) -> 19273 | Y13: =sum(Y3:Y12) -> 19624
A14: 平均年齢 | C14: =C26 -> 19.593789 | D14: =D26 | E14: =E26 -> 20.311841 | F14: =F26 | G14: =G26 -> 20.653254 | H14: =H26 | I14: =I26 -> 21.122405 | J14: =J26 | ... Y14: =Y26 -> 20.98456
C15: =$B3*C3 -> 252 | E15: =$B3*E3 -> 119 | G15: =$B3*G3 -> 98 | I15: =$B3*I3 -> 119 | K15: =$B3*K3 -> 98 | M15: =$B3*M3 -> 112 | O15: =$B3*O3 -> 133 | Q15: =$B3*Q3 -> 77 | S15: =$B3*S3 -> 98 | U15: =$B3*U3 -> 175 | W15: =$B3*W3 -> 140 | Y15: =$B3*Y3 -> 161
C16: =$B4*C4 -> 27768 | E16: =$B4*E4 -> 14388 | G16: =$B4*G4 -> 11976 | I16: =$B4*I4 -> 6828 | K16: =$B4*K4 -> 9132 | M16: =$B4*M4 -> 11988 | O16: =$B4*O4 -> 14052 | Q16: =$B4*Q4 -> 6672 | S16: =$B4*S4 -> 7200 | U16: =$B4*U4 -> 6660 | W16: =$B4*W4 -> 8544 | Y16: =$B4*Y4 -> 8760
C17: =$B5*C5 -> 100963 | E17: =$B5*E5 -> 74681 | G17: =$B5*G5 -> 85646 | I17: =$B5*I5 -> 59262 | K17: =$B5*K5 -> 77520 | M17: =$B5*M5 -> 93313 | O17: =$B5*O5 -> 113152 | Q17: =$B5*Q5 -> 58225 | S17: =$B5*S5 -> 75310 | U17: =$B5*U5 -> 99331 | W17: =$B5*W5 -> 110925 | Y17: =$B5*Y5 -> 113135
C18: =$B6*C6 -> 73546 | E18: =$B6*E6 -> 59796 | G18: =$B6*G6 -> 78012 | I18: =$B6*I6 -> 62920 | K18: =$B6*K6 -> 84700 | M18: =$B6*M6 -> 96778 | O18: =$B6*O6 -> 102586 | Q18: =$B6*Q6 -> 60786 | S18: =$B6*S6 -> 96184 | U18: =$B6*U6 -> 144364 | W18: =$B6*W6 -> 155584 | Y18: =$B6*Y6 -> 168278
C19: =$B7*C7 -> 46197 | E19: =$B7*E7 -> 40743 | G19: =$B7*G7 -> 52542 | I19: =$B7*I7 -> 43335 | K19: =$B7*K7 -> 54648 | M19: =$B7*M7 -> 60912 | O19: =$B7*O7 -> 67095 | Q19: =$B7*Q7 -> 44739 | S19: =$B7*S7 -> 69390 | U19: =$B7*U7 -> 91962 | W19: =$B7*W7 -> 89478 | Y19: =$B7*Y7 -> 84726
C20: =$B8*C8 -> 29184 | E20: =$B8*E8 -> 26272 | G20: =$B8*G8 -> 32416 | I20: =$B8*I8 -> 29056 | K20: =$B8*K8 -> 34464 | M20: =$B8*M8 -> 37536 | O20: =$B8*O8 -> 37248 | Q20: =$B8*Q8 -> 24896 | S20: =$B8*S8 -> 33664 | U20: =$B8*U8 -> 39008 | W20: =$B8*W8 -> 36224 | Y20: =$B8*Y8 -> 32896
C21: =$B10*C10 -> 9366 | E21: =$B10*E10 -> 8022 | G21: =$B10*G10 -> 9198 | I21: =$B10*I10 -> 7938 | K21: =$B10*K10 -> 7896 | M21: =$B10*M10 -> 8274 | O21: =$B10*O10 -> 6258 | Q21: =$B10*Q10 -> 4578 | S21: =$B10*S10 -> 6846 | U21: =$B10*U10 -> 5418 | W21: =$B10*W10 -> 3738 | Y21: =$B10*Y10 -> 2310
C22: =$B11*C11 -> 4700 | E22: =$B11*E11 -> 4089 | G22: =$B11*G11 -> 3854 | I22: =$B11*I11 -> 3337 | K22: =$B11*K11 -> 3149 | M22: =$B11*M11 -> 2397 | O22: =$B11*O11 -> 2209 | Q22: =$B11*Q11 -> 1363 | S22: =$B11*S11 -> 470 | U22: =$B11*U11 -> 658 | W22: =$B11*W11 -> 94 | Y22: =$B11*Y11 -> 235
C23: =$B12*C12 -> 4576 | E23: =$B12*E12 -> 3120 | G23: =$B12*G12 -> 2392 | I23: =$B12*I12 -> 1872 | K23: =$B12*K12 -> 2028 | M23: =$B12*M12 -> 3016 | O23: =$B12*O12 -> 2652 | Q23: =$B12*Q12 -> 1352 | S23: =$B12*S12 -> 780 | U23: =$B12*U12 -> 1040 | W23: =$B12*W12 -> 1404 | Y23: =$B12*Y12 -> 1300
A25: 重み付き和 | C25: =SUM(C15:C23) -> 296552 | E25: =SUM(E15:E23) -> 231230 | G25: =SUM(G15:G23) -> 276134 | I25: =SUM(I15:I23) -> 214667 | K25: =SUM(K15:K23) -> 273635 | M25: =SUM(M15:M23) -> 314326 | O25: =SUM(O15:O23) -> 345385 | Q25: =SUM(Q15:Q23) -> 202688 | S25: =SUM(S15:S23) -> 289942 | U25: =SUM(U15:U23) -> 388616 | W25: =SUM(W15:W23) -> 406131 | Y25: =SUM(Y15:Y23) -> 411801
A26: 平均年齢 | C26: =C25/C13 -> 19.593789 | E26: =E25/E13 -> 20.311841 | G26: =G25/G13 -> 20.653254 | I26: =I25/I13 -> 21.122405 | K26: =K25/K13 -> 20.952144 | M26: =M25/M13 -> 20.791507 | O26: =O25/O13 -> 20.474539 | Q26: =Q25/Q13 -> 20.97351 | S26: =S25/S13 -> 21.26298 | U26: =U25/U13 -> 21.340802 | W26: =W25/W13 -> 21.072537 | Y26: =Y25/Y13 -> 20.98456

Sheet アンケート性別
A1: 男性 | B1: 11676 | C1: 0.7473 | D1: 9289 | E1: 0.8089 | F1: 11268 | G1: 0.8399 | H1: 11442 | I1: 0.8569 | J1: 13557 | K1: 0.8661 | L1: 15320 | M1: 0.8836 | N1: 8834 | O1: 0.8878 | P1: 12966人 | Q1: 0.8898 | R1: 17193人 | S1: 0.8987 | T1: 18485人 | U1: 0.9094 | V1: 18938人 | W1: 0.9066
A2: 女性 | B2: 3392 | C2: 0.2171 | D2: 2194 | E2: 0.1911 | F2: 2148 | G2: 0.1601 | H2: 1911 | I2: 0.1431 | J2: 2096 | K2: 0.1339 | L2: 2018 | M2: 0.1164 | N2: 1116 | O2: 0.1122 | P2: 1606人 | Q2: 0.1102 | R2: 1937人 | S2: 0.1013 | T2: 1841人 | U2: 0.0906 | V2: 1952人 | W2: 0.0934
A3: その他 | B3: 557 | C3: 0.0356

Sheet アンケート年齢性別
A1: 回 | B1: 18 | C1: 17 | D1: 16 | E1: 15 | F1: 14 | G1: 13 | H1: 12 | I1: 11 | J1: 10 | K1: 9 | L1: 8 | M1: 7
A2: 〜9歳 | B2: 0.0024 | C2: 0.0015 | D2: 0.001 | E2: 0.0017 | F2: 0.0011 | G2: 0.0011 | H2: 0.0011 | I2: 0.0011 | J2: 0.001 | K2: 0.0014 | L2: 0.001 | M2: 0.0012
A3: 10〜14歳 | B3: 0.1529 | C3: 0.1053 | D3: 0.0746 | E3: 0.056 | F3: 0.0583 | G3: 0.0661 | H3: 0.0694 | I3: 0.0575 | J3: 0.044 | K3: 0.0305 | L3: 0.0369 | M3: 0.0372
A4: 15〜19歳 | B4: 0.3924 | C4: 0.3859 | D4: 0.3768 | E4: 0.343 | F4: 0.3492 | G4: 0.3631 | H4: 0.3946 | I4: 0.3544 | J4: 0.3249 | K4: 0.3209 | L4: 0.3386 | M4: 0.3391
A5: 20〜24歳 | B5: 0.2209 | C5: 0.2388 | D5: 0.2652 | E5: 0.2814 | F5: 0.2948 | G5: 0.291 | H5: 0.2764 | I5: 0.2859 | J5: 0.3206 | K5: 0.3604 | L5: 0.3669 | M5: 0.3898
A6: 25〜29歳 | B6: 0.113 | C6: 0.1326 | D6: 0.1455 | E6: 0.1579 | F6: 0.155 | G6: 0.1492 | H6: 0.1473 | I6: 0.1715 | J6: 0.1885 | K6: 0.187 | L6: 0.172 | M6: 0.1599
A7: 30〜34歳 | B7: 0.0603 | C7: 0.0721 | D7: 0.0758 | E7: 0.0893 | F7: 0.0825 | G7: 0.0776 | H7: 0.069 | I7: 0.0805 | J7: 0.0771 | K7: 0.0669 | L7: 0.0587 | M7: 0.0524
A8: 35〜39歳 | B8: 0.031 | C8: 0.0342 | D8: 0.035 | E8: 0.0415 | F8: 0.0368 | G8: 0.0318 | H8: 0.0275 | I8: 0.0321 | J8: 0.0301 | K8: 0.024 | L8: 0.0197 | M8: 0.0161
A9: 40〜44歳 | B9: 0.0147 | C9: 0.0168 | D9: 0.0164 | E9: 0.0186 | F9: 0.0144 | G9: 0.013 | H9: 0.0088 | I9: 0.0113 | J9: 0.012 | K9: 0.0071 | L9: 0.0046 | M9: 0.0028
A10: 45〜49歳 | B10: 0.0066 | C10: 0.0076 | D10: 0.0061 | E10: 0.007 | F10: 0.0051 | G10: 0.0034 | H10: 0.0028 | I10: 0.003 | J10: 0.0007 | K10: 0.0008 | L10: 0.0001 | M10: 0.0003
A11: 50歳〜 | B11: 0.0058 | C11: 0.0053 | D11: 0.0034 | E11: 0.0035 | F11: 0.003 | G11: 0.0038 | H11: 0.003 | I11: 0.0027 | J11: 0.0011 | K11: 0.0011 | L11: 0.0014 | M11: 0.0013
A12: 合計数
A13: 平均年齢 | B13: =B25 | C13: =C25 | D13: =D25 | E13: =E25 | F13: =F25 | G13: =G25 | H13: =H25 | I13: =I25 | ... L13: =L25
A18: 平均年齢
A20: 19.593789
A22: 20.311841
A24: 20.653254
A26: 21.122405
A28: 20.952144
A30: 20.791507
A32: 20.474539
A34: 20.97351
A36: 21.26298
A38: 21.340802
A40: 21.072537
A42: 20.98456
A44: 回 | B44: 男性 | C44: 女性
A45: 18 | B45: 0.7473 | C45: 0.2171
A46: 17 | B46: 0.8089 | C46: 0.1911
A47: 16 | B47: 0.8399 | C47: 0.1601
A48: 15 | B48: 0.8569 | C48: 0.1431
A49: 14 | B49: 0.8661 | C49: 0.1339
A50: 13 | B50: 0.8836 | C50: 0.1164
A51: 12 | B51: 0.8878 | C51: 0.1122
A52: 11 | B52: 0.8898 | C52: 0.1102
A53: 10 | B53: 0.8987 | C53: 0.1013
A54: 9 | B54: 0.9094 | C54: 0.0906
A55: 8 | B55: 0.9066 | C55: 0.0934
A56: 7 | B56: 0.9094 | C56: 0.0906

Sheet アンケート地域
D1: 18 | E1: 17 | F1: 16 | G1: 15 | H1: 14 | I1: 13 | J1: 12
A2: 北海道 | D2: 496 | E2: 429 | F2: 426 | G2: 399 | H2: 491 | I2: 598 | J2: 715
A3: 北東北（青森・岩手・秋田） | D3: 280 | E3: 212 | F3: 220 | G3: 187 | H3: 272 | I3: 360 | J3: 384
A4: 南東北（宮城・山形・福島） | D4: 497 | E4: 394 | F4: 442 | G4: 338 | H4: 444 | I4: 563 | J4: 628
A5: 北関東（茨城・栃木・群馬） | D5: 654 | E5: 505 | F5: 589 | G5: 510 | H5: 634 | I5: 750 | J5: 805
A6: 南関東（埼玉・千葉・東京・神奈川） | D6: 3879 | E6: 2967 | F6: 3765 | G6: 2958 | H6: 3813 | I6: 4545 | J6: 5019
A7: 北陸（富山・石川・福井） | D7: 263 | E7: 188 | F7: 230 | G7: 191 | H7: 255 | I7: 301 | J7: 351
A8: 甲信越（新潟・山梨・長野） | D8: 506 | E8: 383 | F8: 420 | G8: 335 | H8: 471 | I8: 532 | J8: 597
A9: 東海（愛知・三重・岐阜・静岡） | D9: 1411 | E9: 1017 | F9: 1221 | G9: 1006 | H9: 1285 | I9: 1534 | J9: 1692
A10: 近畿（大阪・京都・兵庫・奈良・滋賀・和歌山） | D10: 1776 | E10: 1284 | F10: 1663 | G10: 1259 | H10: 1675 | I10: 2048 | J10: 2339
A11: 中国（鳥取・島根・岡山・広島・山口） | D11: 587 | E11: 435 | F11: 524 | G11: 425 | H11: 558 | I11: 629 | J11: 729
A12: 四国（徳島・愛媛・香川・高知） | D12: 279 | E12: 226 | F12: 236 | G12: 168 | H12: 242 | I12: 335 | J12: 367
A13: 九州北部（福岡・佐賀・長崎・大分） | D13: 567 | E13: 402 | F13: 425 | G13: 398 | H13: 502 | I13: 638 | J13: 670
... A44: 日本国外：オセアニア | D44: 0.0043 | E44: 0.0033 | F44: 0.003 | G44: 0.0028 | H44: 0.0023 | I44: 0.0018 | J44: 0.002

Sheet 非整数音楽追加
A1: Track Name | B1: Notes | C1: 作品 | D1: 年 | E1: 人気投票 | F1: 番号
A2: 緋想天 | B2: （タイトル） | C2: 緋想天 | D2: 2008 | E2: 5 | F2: 10.5
A3: 日常坐臥 | B3: （会話曲） | C3: 緋想天 | D3: 2008 | E3: 5 | F3: 10.5
A4: 地の色は黄色 | B4: （ステージ博麗神社(壊)） | C4: 緋想天 | D4: 2008 | E4: 5 | F4: 10.5
A5: 甲論乙駁 | B5: （会話曲） | C5: 緋想天 | D5: 2008 | E5: 5 | F5: 10.5
A6: 風光明媚 | B6: （会話曲） | C6: 緋想天 | D6: 2008 | E6: 5 | F6: 10.5
A7: 香る樹葉花 | B7: （ステージ魔法の森） | C7: 緋想天 | D7: 2008 | E7: 5 | F7: 10.5
A8: 踊る水飛沫 | B8: （ステージ玄武の沢） | C8: 緋想天 | D8: 2008 | E8: 5 | F8: 10.5
A9: 以魚駆蠅 | B9: （会話曲） | C9: 緋想天 | D9: 2008 | E9: 5 | F9: 10.5
A10: 放縦不羈 | B10: （会話曲） | C10: 緋想天 | D10: 2008 | E10: 5 | F10: 10.5
A11: 嘲りの遊戯 | B11: （ステージ妖怪の山） | C11: 緋想天 | D11: 2008 | E11: 5 | F11: 10.5
A12: 冷吟閑酔 | B12: （会話曲） | C12: 緋想天 | D12: 2008 | E12: 5 | F12: 10.5
A13: 雲外蒼天 | B13: （会話曲 衣玖戦前など） | C13: 緋想天 | D13: 2008 | E13: 5 | F13: 10.5
... A26: 異変の種子 | B26: 本編中に「異変の種子」が成長していくので同一記事にまとめた。 | C26: 憑依華 | D26: 2017 | E26: 13 | F26: 15.5
A27: 意気揚々 | C27: 憑依華 | D27: 2017 | E27: 13 | F27: 15.5
A28: 知略縦横 | C28: 憑依華 | D28: 2017 | E28: 13 | F28: 15.5
A29: 異心同体 | C29: 憑依華 | D29: 2017 | E29: 13 | F29: 15.5
A30: 合縁奇縁 | C30: 憑依華 | D30: 2017 | E30: 13 | F30: 15.5
A31: 憑依投合 | C31: 憑依華 | D31: 2017 | E31: 13 | F31: 15.5
A32: 連帯責人 | C32: 憑依華 | D32: 2017 | E32: 13 | F32: 15.5
A33: 壮言大語 | C33: 憑依華 | D33: 2017 | E33: 13 | F33: 15.5
A34: 開演間近 | C34: 憑依華 | D34: 2017 | E34: 13 | F34: 15.5
A35: 天衣無縫 ～ Yellow Lily | C35: 憑依華 | D35: 2017 | E35: 13 | F35: 15.5
A36: エンディング | C36: 憑依華 | D36: 2017 | E36: 13 | F36: 15.5
A37: 行雲流水 | C37: 憑依華 | D37: 2017 | E37: 13 | F37: 15.5
A38: 未だ蕾む憑依華 | C38: 憑依華 | D38: 2017 | E38: 13 | F38: 15.5
... A40: 悠久の蒸気機関 | C40: 憑依華 | D40: 2017 | E40: 13 | F40: 15.5
A41: 地の色は黄色 ～ Primrose | B41: 博麗神社） | C41: 憑依華 | D41: 2017 | E41: 13 | F41: 15.5
A42: マッシュルーム・ワルツ | B42: 香霖堂） | C42: 憑依華 | D42: 2017 | E42: 13 | F42: 15.5
A43: 聖輦船空を往く | B43: 雲上の宝船） | C43: 憑依華 | D43: 2017 | E43: 13 | F43: 15.5
A44: 法力の下の平等 | B44: 命蓮寺） | C44: 憑依華 | D44: 2017 | E44: 13 | F44: 15.5
A45: 恒常不変の参廟祀 | B45: 夢殿大祀廟） | C45: 憑依華 | D45: 2017 | E45: 13 | F45: 15.5
A46: 光り輝く天球儀 | B46: 神霊廟） | C46: 憑依華 | D46: 2017 | E46: 13 | F46: 15.5
A47: 沢の河童の技術力 | B47: 玄武の沢） | C47: 憑依華 | D47: 2017 | E47: 13 | F47: 15.5
A48: 地底に咲く薔薇 | B48: 地霊殿） | C48: 憑依華 | D48: 2017 | E48: 13 | F48: 15.5
A49: 深緑の狸森にて | B49: 妖怪狸の森） | C49: 憑依華 | D49: 2017 | E49: 13 | F49: 15.5
A50: 心綺楼演舞 | B50: 人間の里） | C50: 憑依華 | D50: 2017 | E50: 13 | F50: 15.5
A51: 不滅のレッドソウル | B51: 迷いの竹林） | C51: 憑依華 | D51: 2017 | E51: 13 | F51: 15.5
A52: 落日に映える逆さ城 | B52: 輝針城） | C52: 憑依華 | D52: 2017 | E52: 13 | F52: 15.5
... A59: 今宵は飄逸なエゴイスト(Live ver) ～ Egoistic Flowers. | B59: 太陽のライブステージ） | C59: 憑依華 | D59: 2017 | E59: 13 | F59: 15.5
...

Sheet アンケート作品
A1: 東方プロジェクトを知った時期 | B1: 18 | C1: 17 | D1: 16 | E1: 15 | F1: 14 | G1: 13 | H1: 12 | I1: 11 | J1: 10
A2: 旧作～秋霜玉（2000年12月） | B2: 81 | C2: 68 | D2: 63 | E2: 58 | F2: 73 | G2: 107 | H2: 119 | I2: 50 | J2: 101
A3: 秋霜玉～紅魔郷（2002年8月） | B3: 156 | C3: 119 | D3: 133 | E3: 88 | F3: 155 | G3: 178 | H3: 199 | I3: 95 | J3: 89
A4: 紅魔郷～妖々夢（2003年8月） | B4: 413 | C4: 316 | D4: 463 | E4: 373 | F4: 489 | G4: 685 | H4: 729 | I4: 469 | J4: 622
A5: 妖々夢～永夜抄（2004年8月） | B5: 199 | C5: 215 | D5: 253 | E5: 283 | F5: 354 | G5: 469 | H5: 570 | I5: 362 | J5: 561
A6: 永夜抄～萃夢想（2004年12月） | B6: 139 | C6: 124 | D6: 199 | E6: 221 | F6: 292 | G6: 353 | H6: 436 | I6: 292 | J6: 495
A7: 萃夢想～花映塚（2005年8月） | B7: 102 | C7: 88 | D7: 152 | E7: 140 | F7: 161 | G7: 235 | H7: 303 | I7: 215 | J7: 323
A8: 花映塚～文花帖（2005年12月） | B8: 78 | C8: 92 | D8: 148 | E8: 134 | F8: 174 | G8: 234 | H8: 294 | I8: 177 | J8: 316
A9: 文花帖～求聞史紀（2006年12月） | B9: 115 | C9: 117 | D9: 149 | E9: 169 | F9: 242 | G9: 327 | H9: 366 | I9: 250 | J9: 343
A10: 求聞史紀～風神録（2007年8月） | B10: 406 | C10: 403 | D10: 545 | E10: 562 | F10: 797 | G10: 1019 | H10: 1218 | I10: 910 | J10: 1144
A11: 風神録～地霊殿（2008年8月） | B11: 827 | C11: 794 | D11: 1197 | E11: 1130 | F11: 1600 | G11: 2066 | H11: 2387 | I11: 1571 | J11: 2670
A12: 地霊殿～星蓮船（2009年8月） | B12: 660 | C12: 647 | D12: 968 | E12: 886 | F12: 1139 | G12: 1450 | H12: 1779 | I12: 1182 | J12: 2008
... A16: 求聞口授～輝針城（2013年8月） | B16: 857 | C16: 772 | D16: 1102 | E16: 891 | F16: 1164 | G16: 1531 | H16: 1926 | I16: 1013 | J16: 510
A17: 輝針城～アマノジャク（2014年5月） | B17: 1082 | C17: 954 | D17: 1294 | E17: 994 | F17: 1398 | G17: 1663 | H17: 1780 | I17: 637 | J17: 0 | K17: 0
A18: アマノジャク～紺珠伝（2015年8月） | B18: 1399 | C18: 1075 | D18: 1286 | E18: 1006 | F18: 1259 | G18: 1308 | H18: 767 | I18: 345 | J18: 0 | K18: 0
A19: 紺珠伝～旧約酒場（2016年8月） | B19: 1440 | C19: 1019 | D19: 1085 | E19: 762 | F19: 915 | G19: 475 | H19: 242 | I19: 0 | J19: 0 | K19: 0
A20: 旧約酒場～天空璋（2017年8月） | B20: 1471 | C20: 1066 | D20: 1120 | E20: 386 | F20: 297 | G20: 151 | H20: 0 | I20: 0 | J20: 0 | K20: 0
A21: 天空璋～鬼形獣（2019年8月） | B21: 1966 | C21: 1246 | D21: 808 | E21: 382 | F21: 98 | G21: 0 | H21: 0 | I21: 0 | J21: 0 | K21: 0
A22: 鬼形獣～虹龍洞（2021年5月） | B22: 1239 | C22: 588 | D22: 371 | E22: 0 | F22: 0 | G22: 0 | H22: 0 | I22: 0 | J22: 0 | K22: 0
A23: 虹龍洞～ | B23: 791 | C23: 207 | D23: 0 | E23: 0 | F23: 0 | G23: 0 | H23: 0 | I23: 0 | J23: 0 | K23: 0
A25: 合計 | B25: =SUM(B1:B23) -> 15539 | C25: =SUM(C1:C23) -> 11777 | D25: =SUM(D1:D23) -> 13850 | E25: =SUM(E1:E23) -> 10589 | F25: =SUM(F1:F23) -> 13724 | G25: =SUM(G1:G23) -> 16008 | H25: =SUM(H1:H23) -> 17800 | I25: =SUM(I1:I23) -> 10343 | J25: =SUM(J1:J23) -> 15381
A27: 東方プロジェクトを知った時期(割合) | B27: =B1 -> 18 | C27: =C1 -> 17 | D27: =D1 -> 16 | E27: =E1 -> 15 | F27: =F1 -> 14 | G27: =G1 -> 13 | H27: =H1 -> 12 | I27: =I1 -> 11 | J27: =J1 -> 10
A28: 旧作～秋霜玉（2000年12月） | B28: =B2/B$25 -> 0.0052126906 | C28: =C2/C$25 -> 0.0057739662 | D28: =D2/D$25 -> 0.0045487365 | E28: =E2/E$25 -> 0.0054773822 | F28: =F2/F$25 -> 0.0053191489 | G28: =G2/G$25 -> 0.0066841579 | H28: =H2/H$25 -> 0.0066853933 | I28: =I2/I$25 -> 0.0048341874 | J28: =J2/J$25 -> 0.0065665431
A29: 秋霜玉～紅魔郷（2002年8月） | B29: =B3/B$25 -> 0.010039256 | C29: =C3/C$25 -> 0.010104441 | D29: =D3/D$25 -> 0.0096028881 | E29: =E3/E$25 -> 0.0083105109 | F29: =F3/F$25 -> 0.011294083 | G29: =G3/G$25 -> 0.01111944 | H29: =H3/H$25 -> 0.011179775 | I29: =I3/I$25 -> 0.009184956 | J29: =J3/J$25 -> 0.0057863598
A30: 紅魔郷～妖々夢（2003年8月） | B30: =B4/B$25 -> 0.026578287 | C30: =C4/C$25 -> 0.026831961 | D30: =D4/D$25 -> 0.033429603 | E30: =E4/E$25 -> 0.035225234 | F30: =F4/F$25 -> 0.035631011 | G30: =G4/G$25 -> 0.042791104 | H30: =H4/H$25 -> 0.040955056 | I30: =I4/I$25 -> 0.045344678 | J30: =J4/J$25 -> 0.040439503
A31: 妖々夢～永夜抄（2004年8月） | B31: =B5/B$25 -> 0.012806487 | C31: =C5/C$25 -> 0.018255923 | D31: =D5/D$25 -> 0.018267148 | E31: =E5/E$25 -> 0.026725848 | F31: =F5/F$25 -> 0.025794229 | G31: =G5/G$25 -> 0.029297851 | H31: =H5/H$25 -> 0.032022472 | I31: =I5/I$25 -> 0.034999517 | J31: =J5/J$25 -> 0.036473571
A32: 永夜抄～萃夢想（2004年12月） | B32: =B6/B$25 -> 0.0089452346 | C32: =C6/C$25 -> 0.010528997 | D32: =D6/D$25 -> 0.014368231 | E32: =E6/E$25 -> 0.020870715 | F32: =F6/F$25 -> 0.021276596 | G32: =G6/G$25 -> 0.022051474 | H32: =H6/H$25 -> 0.024494382 | I32: =I6/I$25 -> 0.028231654 | J32: =J6/J$25 -> 0.032182563
A33: 萃夢想～花映塚（2005年8月） | B33: =B7/B$25 -> 0.006564129 | C33: =C7/C$25 -> 0.0074721916 | D33: =D7/D$25 -> 0.010974729 | E33: =E7/E$25 -> 0.013221267 | F33: =F7/F$25 -> 0.011731274 | G33: =G7/G$25 -> 0.01468016 | H33: =H7/H$25 -> 0.017022472 | I33: =I7/I$25 -> 0.020787006 | J33: =J7/J$25 -> 0.020999935
A34: 花映塚～文花帖（2005年12月） | B34: =B8/B$25 -> 0.005019628 | C34: =C8/C$25 -> 0.0078118366 | D34: =D8/D$25 -> 0.010685921 | E34: =E8/E$25 -> 0.012654642 | F34: =F8/F$25 -> 0.012678519 | G34: =G8/G$25 -> 0.014617691 | H34: =H8/H$25 -> 0.016516854 | I34: =I8/I$25 -> 0.017113023 | J34: =J8/J$25 -> 0.020544828
A35: 文花帖～求聞史紀（2006年12月） | B35: =B9/B$25 -> 0.0074007336 | C35: =C9/C$25 -> 0.0099346183 | D35: =D9/D$25 -> 0.010758123 | E35: =E9/E$25 -> 0.015959958 | F35: =F9/F$25 -> 0.017633343 | G35: =G9/G$25 -> 0.020427286 | H35: =H9/H$25 -> 0.020561798 | I35: =I9/I$25 -> 0.024170937 | J35: =J9/J$25 -> 0.022300241
A36: 求聞史紀～風神録（2007年8月） | B36: =B10/B$25 -> 0.026127807 | C36: =C10/C$25 -> 0.034219241 | D36: =D10/D$25 -> 0.039350181 | E36: =E10/E$25 -> 0.053073945 | F36: =F10/F$25 -> 0.058073448 | G36: =G10/G$25 -> 0.063655672 | H36: =H10/H$25 -> 0.068426966 | I36: =I10/I$25 -> 0.08798221 | J36: =J10/J$25 -> 0.074377479
A37: 風神録～地霊殿（2008年8月） | B37: =B11/B$25 -> 0.053220928 | C37: =C11/C$25 -> 0.067419547 | D37: =D11/D$25 -> 0.086425993 | E37: =E11/E$25 -> 0.10671452 | F37: =F11/F$25 -> 0.11658409 | G37: =G11/G$25 -> 0.12906047 | H37: =H11/H$25 -> 0.13410112 | I37: =I11/I$25 -> 0.15189017 | J37: =J11/J$25 -> 0.17359079
A38: 地霊殿～星蓮船（2009年8月） | B38: =B12/B$25 -> 0.042473776 | C38: =C12/C$25 -> 0.05493759 | D38: =D12/D$25 -> 0.069891697 | E38: =E12/E$25 -> 0.083671735 | F38: =F12/F$25 -> 0.082993296 | G38: =G12/G$25 -> 0.09057971 | H38: =H12/H$25 -> 0.09994382 | I38: =I12/I$25 -> 0.11428019 | J38: =J12/J$25 -> 0.13055068
A39: 星蓮船～妖精大戦争（2010年8月） | B39: =B13/B$25 -> 0.03932042 | C39: =C13/C$25 -> 0.049842914 | D39: =D13/D$25 -> 0.055234657 | E39: =E13/E$25 -> 0.061856644 | F39: =F13/F$25 -> 0.072063538 | G39: =G13/G$25 -> 0.072588706 | H39: =H13/H$25 -> 0.083314607 | I39: =I13/I$25 -> 0.086338586 | J39: =J13/J$25 -> 0.11013588
... A49: 虹龍洞～ | B49: =B23/B$25 -> 0.050904177 | C49: =C23/C$25 -> 0.017576632 | D49: =D23/D$25 -> 0 | E49: =E23/E$25 -> 0 | F49: =F23/F$25 -> 0 | G49: =G23/G$25 -> 0 | H49: =H23/H$25 -> 0 | I49: =I23/I$25 -> 0 | J49: =J23/J$25 -> 0
A82: 東方プロジェクトを知った時期 | B82: 旧作～秋霜玉（2000年12月） | C82: 秋霜玉～紅魔郷（2002年8月） | D82: 紅魔郷～妖々夢（2003年8月） | E82: 妖々夢～永夜抄（2004年8月） | F82: 永夜抄～萃夢想（2004年12月） | G82: 萃夢想～花映塚（2005年8月） | H82: 花映塚～文花帖（2005年12月） | I82: 文花帖～求聞史紀（2006年12月） | J82: 求聞史紀～風神録（2007年8月） | K82: 風神録～地霊殿（2008年8月） | L82: 地霊殿～星蓮船（2009年8月） | M82: 星蓮船～妖精大戦争（2010年8月） | N82: 妖精大戦争～神霊廟（2011年8月） | O82: 神霊廟～求聞口授（2012年4月） | P82: 求聞口授～輝針城（2013年8月） | Q82: 輝針城～アマノジャク（2014年5月） | R82: アマノジャク～紺珠伝（2015年8月） | S82: 紺珠伝～旧約酒場（2016年8月） | T82: 旧約酒場～天空璋（2017年8月） | U82: 天空璋～鬼形獣（2019年8月） | V82: 鬼形獣～虹龍洞（2021年5月） | W82: 虹龍洞～
A83: 18 | B83: 81 | C83: 156 | D83: 413 | E83: 199 | F83: 139 | G83: 102 | H83: 78 | I83: 115 | J83: 406 | K83: 827 | L83: 660 | M83: 611 | N83: 652 | O83: 837 | P83: 857 | Q83: 1082 | R83: 1399 | S83: 1440 | T83: 1471 | U83: 1966 | V83: 1239 | W83: 791
A84: 17 | B84: 68 | C84: 119 | D84: 316 | E84: 215 | F84: 124 | G84: 88 | H84: 92 | I84: 117 | J84: 403 | K84: 794 | L84: 647 | M84: 587 | N84: 582 | O84: 681 | P84: 772 | Q84: 954 | R84: 1075 | S84: 1019 | T84: 1066 | U84: 1246 | V84: 588 | W84: 207
A85: 16 | B85: 63 | C85: 133 | D85: 463 | E85: 253 | F85: 199 | G85: 152 | H85: 148 | I85: 149 | J85: 545 | K85: 1197 | L85: 968 | M85: 765 | N85: 723 | O85: 1010 | P85: 1102 | Q85: 1294 | R85: 1286 | S85: 1085 | T85: 1120 | U85: 808 | V85: 371 | W85: 0
A86: 15 | B86: 58 | C86: 88 | D86: 373 | E86: 283 | F86: 221 | G86: 140 | H86: 134 | I86: 169 | J86: 562 | K86: 1130 | L86: 886 | M86: 655 | N86: 636 | O86: 818 | P86: 891 | Q86: 994 | R86: 1006 | S86: 762 | T86: 386 | U86: 382 | V86: 0 | W86: 0
...
